Workbook

Sheet Order Form
J2: MALAYSIA DISTRIBUTOR
J3: ORDER CALCULATION FORM - WEST MALAYSIA
B6: Herbalife Products Malaysia Sdn Bhd | J6: Distributor Services Hotline | L6: (603) 2706 9888
B7: 199301027403 (282141-M) AJL No. 931586 | J7: Distributor Services Email | L7: memberservices_my@herbalife.com
B8: Ground Floor Plaza See Hoy Chan
B9: Jalan Raja Chulan
B10: 50200 Kuala Lumpur | J10: Order Month:
B12: Updated as of May 19, 2026
B13: DELIVERY METHOD
B14: PURCHASED BY | H14: SHIP TO (FOR DELIVERY ONLY)
B15: Name | H15: Name
B16: ID No. | H16: Address
B17: FULLY QUALIFIED SUPERVISOR
B18: Name | H18: Phone:
B19: ID No. | H19: PAYMENT INFORMATION - Wire transfer
B20: Month & Year of Qualification | H20: Maybank (Herbalife Products Malaysia Sdn Bhd - Acc No: 5142 7123 2600)
E21: Month | G21: Year | H21: Amount Transfer
B22: QUALIFYING SUPERVISOR - TEMP 50% | H22: Name of Your Bank
B23: Name | H23: Date Transfer
B24: ID No. | H24: Time Transfer
B25: SHIPPING INSTRUCTION (FOR DELIVERY ONLY)
B28: Discount | C28: 0.5 | D28: * Total amount tabulated in this Email Order Form may vary from actual order tabulated from the system
B30: Stock No | C30: Product Name | I30: Qty | J30: Total VP | K30: Unit Price | L30: Total Price | O30: Retail Price | P30: Total Retail
C32: =IF(B32<>"",VLOOKUP(B32,'Price List'!A:J,2,0),"") | J32: =IF(B32="","",VLOOKUP(B32,'Price List'!A:J,4,0)*I32) | K32: =IF(B32="","",(VLOOKUP(B32,'Price List'!A:J,6,0)-(VLOOKUP(B32,'Price List'!A:K,11,0)*$C$28))) | L32: =IF(K32="","",(K32*I32)) | O32: =IF(B32<>"",VLOOKUP(B32,'Price List'!A:J,6,0),"") | P32: =IF(B32="","",O32*I32)
C33: =IF(B33<>"",VLOOKUP(B33,'Price List'!A:J,2,0),"") | J33: =IF(B33="","",VLOOKUP(B33,'Price List'!A:J,4,0)*I33) | K33: =IF(B33="","",(VLOOKUP(B33,'Price List'!A:J,6,0)-(VLOOKUP(B33,'Price List'!A:K,11,0)*$C$28))) | L33: =IF(K33="","",(K33*I33)) | O33: =IF(B33<>"",VLOOKUP(B33,'Price List'!A:J,6,0),"") | P33: =IF(B33="","",O33*I33)
C34: =IF(B34<>"",VLOOKUP(B34,'Price List'!A:J,2,0),"") | J34: =IF(B34="","",VLOOKUP(B34,'Price List'!A:J,4,0)*I34) | K34: =IF(B34="","",(VLOOKUP(B34,'Price List'!A:J,6,0)-(VLOOKUP(B34,'Price List'!A:K,11,0)*$C$28))) | L34: =IF(K34="","",(K34*I34)) | O34: =IF(B34<>"",VLOOKUP(B34,'Price List'!A:J,6,0),"") | P34: =IF(B34="","",O34*I34)
C35: =IF(B35<>"",VLOOKUP(B35,'Price List'!A:J,2,0),"") | J35: =IF(B35="","",VLOOKUP(B35,'Price List'!A:J,4,0)*I35) | K35: =IF(B35="","",(VLOOKUP(B35,'Price List'!A:J,6,0)-(VLOOKUP(B35,'Price List'!A:K,11,0)*$C$28))) | L35: =IF(K35="","",(K35*I35)) | O35: =IF(B35<>"",VLOOKUP(B35,'Price List'!A:J,6,0),"") | P35: =IF(B35="","",O35*I35)
C36: =IF(B36<>"",VLOOKUP(B36,'Price List'!A:J,2,0),"") | J36: =IF(B36="","",VLOOKUP(B36,'Price List'!A:J,4,0)*I36) | K36: =IF(B36="","",(VLOOKUP(B36,'Price List'!A:J,6,0)-(VLOOKUP(B36,'Price List'!A:K,11,0)*$C$28))) | L36: =IF(K36="","",(K36*I36)) | O36: =IF(B36<>"",VLOOKUP(B36,'Price List'!A:J,6,0),"") | P36: =IF(B36="","",O36*I36)
C37: =IF(B37<>"",VLOOKUP(B37,'Price List'!A:J,2,0),"") | J37: =IF(B37="","",VLOOKUP(B37,'Price List'!A:J,4,0)*I37) | K37: =IF(B37="","",(VLOOKUP(B37,'Price List'!A:J,6,0)-(VLOOKUP(B37,'Price List'!A:K,11,0)*$C$28))) | L37: =IF(K37="","",(K37*I37)) | O37: =IF(B37<>"",VLOOKUP(B37,'Price List'!A:J,6,0),"") | P37: =IF(B37="","",O37*I37)
C38: =IF(B38<>"",VLOOKUP(B38,'Price List'!A:J,2,0),"") | J38: =IF(B38="","",VLOOKUP(B38,'Price List'!A:J,4,0)*I38) | K38: =IF(B38="","",(VLOOKUP(B38,'Price List'!A:J,6,0)-(VLOOKUP(B38,'Price List'!A:K,11,0)*$C$28))) | L38: =IF(K38="","",(K38*I38)) | O38: =IF(B38<>"",VLOOKUP(B38,'Price List'!A:J,6,0),"") | P38: =IF(B38="","",O38*I38)
C39: =IF(B39<>"",VLOOKUP(B39,'Price List'!A:J,2,0),"") | J39: =IF(B39="","",VLOOKUP(B39,'Price List'!A:J,4,0)*I39) | K39: =IF(B39="","",(VLOOKUP(B39,'Price List'!A:J,6,0)-(VLOOKUP(B39,'Price List'!A:K,11,0)*$C$28))) | L39: =IF(K39="","",(K39*I39)) | O39: =IF(B39<>"",VLOOKUP(B39,'Price List'!A:J,6,0),"") | P39: =IF(B39="","",O39*I39)
C40: =IF(B40<>"",VLOOKUP(B40,'Price List'!A:J,2,0),"") | J40: =IF(B40="","",VLOOKUP(B40,'Price List'!A:J,4,0)*I40) | K40: =IF(B40="","",(VLOOKUP(B40,'Price List'!A:J,6,0)-(VLOOKUP(B40,'Price List'!A:K,11,0)*$C$28))) | L40: =IF(K40="","",(K40*I40)) | O40: =IF(B40<>"",VLOOKUP(B40,'Price List'!A:J,6,0),"") | P40: =IF(B40="","",O40*I40)
C41: =IF(B41<>"",VLOOKUP(B41,'Price List'!A:J,2,0),"") | J41: =IF(B41="","",VLOOKUP(B41,'Price List'!A:J,4,0)*I41) | K41: =IF(B41="","",(VLOOKUP(B41,'Price List'!A:J,6,0)-(VLOOKUP(B41,'Price List'!A:K,11,0)*$C$28))) | L41: =IF(K41="","",(K41*I41)) | O41: =IF(B41<>"",VLOOKUP(B41,'Price List'!A:J,6,0),"") | P41: =IF(B41="","",O41*I41)
C42: =IF(B42<>"",VLOOKUP(B42,'Price List'!A:J,2,0),"") | J42: =IF(B42="","",VLOOKUP(B42,'Price List'!A:J,4,0)*I42) | K42: =IF(B42="","",(VLOOKUP(B42,'Price List'!A:J,6,0)-(VLOOKUP(B42,'Price List'!A:K,11,0)*$C$28))) | L42: =IF(K42="","",(K42*I42)) | O42: =IF(B42<>"",VLOOKUP(B42,'Price List'!A:J,6,0),"") | P42: =IF(B42="","",O42*I42)
C43: =IF(B43<>"",VLOOKUP(B43,'Price List'!A:J,2,0),"") | J43: =IF(B43="","",VLOOKUP(B43,'Price List'!A:J,4,0)*I43) | K43: =IF(B43="","",(VLOOKUP(B43,'Price List'!A:J,6,0)-(VLOOKUP(B43,'Price List'!A:K,11,0)*$C$28))) | L43: =IF(K43="","",(K43*I43)) | O43: =IF(B43<>"",VLOOKUP(B43,'Price List'!A:J,6,0),"") | P43: =IF(B43="","",O43*I43)
... C58: =IF(B58<>"",VLOOKUP(B58,'Price List'!A:J,2,0),"") | J58: =IF(B58="","",VLOOKUP(B58,'Price List'!A:J,4,0)*I58) | K58: =IF(B58="","",(VLOOKUP(B58,'Price List'!A:J,6,0)-(VLOOKUP(B58,'Price List'!A:K,11,0)*$C$28))) | L58: =IF(K58="","",(K58*I58)) | O58: =IF(B58<>"",VLOOKUP(B58,'Price List'!A:J,6,0),"") | P58: =IF(B58="","",O58*I58)
I59: Total Retail Price | L59: =SUM(L32:M58) -> 0 | O59: =IF(B59<>"",VLOOKUP(B59,'Price List'!A:J,6,0),"") | P59: =IF(B59="","",O59*I59)
B60: PLEASE COMPLETE FOR THIS ORDER | I60: Freight | L60: =IF(AND(N13=4,P60<1000.99),15,IF(AND(N13=5,P60<1000.99),30,0))*1.06 -> 0 | P60: =SUM(P32:P59) -> 0
B61: Volume Points for this order | F61: =SUM(J32:J58) -> 0 | I61: Total Amount Due | L61: =SUM(L59:M60) -> 0
B62: Volume Points for previous orders | F62: 0
...

Sheet Price List
A1: Malaysia Price List updated as of May 19, 2026
A2: Stock No | B2: Product Name | C2: Qty | D2: Volume Points | E2: Earn Base | F2: Retail Price | G2: 0.25 | H2: 0.35 | I2: 0.42 | J2: 0.5 | K2: Earn Base Disc calculation
A3: INNER NUTRITION/NUTRISI DALAMAN
A4: Core Nutrition/Nutrisi Utama
A5: 4462 | B5: Formula 1 - Banana Cream Flavour | C5: 1 | D5: 23.95 | E5: 193.92 | F5: 212.03 | G5: 163.55 | H5: 144.16 | I5: 130.58 | J5: 115.07 | K5: 193.92
A6: 4465 | B6: Formula 1 - Cafe Latte Flavour | C6: 1 | D6: 23.95 | E6: 193.92 | F6: 212.03 | G6: 163.55 | H6: 144.16 | I6: 130.58 | J6: 115.07 | K6: 193.92
A7: 4466 | B7: Formula 1 - Vanilla Cream Flavour | C7: 1 | D7: 23.95 | E7: 193.92 | F7: 212.03 | G7: 163.55 | H7: 144.16 | I7: 130.58 | J7: 115.07 | K7: 193.92
A8: 4467 | B8: Formula 1 - Cookie Crunch Flavour | C8: 1 | D8: 23.95 | E8: 193.92 | F8: 212.03 | G8: 163.55 | H8: 144.16 | I8: 130.58 | J8: 115.07 | K8: 193.92
A9: 4468 | B9: Formula 1 - Smooth Chocolate Flavour | C9: 1 | D9: 23.95 | E9: 193.92 | F9: 212.03 | G9: 163.55 | H9: 144.16 | I9: 130.58 | J9: 115.07 | K9: 193.92
A10: 4470 | B10: Formula 1 - Summer Berries Flavour | C10: 1 | D10: 23.95 | E10: 193.92 | F10: 212.03 | G10: 163.55 | H10: 144.16 | I10: 130.58 | J10: 115.07 | K10: 193.92
A11: 072K | B11: Formula 1 Select | C11: 1 | D11: 30.65 | E11: 268.86 | F11: 293.96 | G11: 226.74 | H11: 199.86 | I11: 181.04 | J11: 159.53 | K11: 268.86
A12: 0242 | B12: Formula 3 - Blended Soy and Whey Protein Powder | C12: 1 | D12: 17.95 | E12: 152.91 | F12: 174.41 | G12: 136.18 | H12: 120.89 | I12: 110.19 | J12: 97.95 | K12: 152.91
A13: 0105 | B13: Tea Mix with Hibiscus - Original Flavour 51g | C13: 1 | D13: 19.95 | E13: 162.11 | F13: 177.25 | G13: 136.72 | H13: 120.51 | I13: 109.16 | J13: 96.19 | K13: 162.11
A14: 0106 | B14: Tea Mix with Hibiscus - Original Flavour 102g | C14: 1 | D14: 34.95 | E14: 280.91 | F14: 307.14 | G14: 236.91 | H14: 208.82 | I14: 189.16 | J14: 166.68 | K14: 280.91
A15: 0190 | B15: Tea Mix with Hibiscus - Peach Flavour 102g | C15: 1 | D15: 34.95 | E15: 280.91 | F15: 307.14 | G15: 236.91 | H15: 208.82 | I15: 189.16 | J15: 166.68 | K15: 280.91
A16: 2121 | B16: Tea Mix with Hibiscus - Honey Ginger Flavour 102g | C16: 1 | D16: 34.95 | E16: 280.91 | F16: 307.14 | G16: 236.91 | H16: 208.82 | I16: 189.16 | J16: 166.68 | K16: 280.91
A17: 3115 | B17: Multivitamins & Minerals | C17: 1 | D17: 19.95 | E17: 132.43 | F17: 144.8 | G17: 111.69 | H17: 98.45 | I17: 89.18 | J17: 78.58 | K17: 132.43
A18: Weight Management Program Pack/ Pek Program Pengurusan Berat Badan
A19: (with additional 2 unit of same Formula 1 flavours/ dengan tambahan 2 unit perisa Formula 1 yang sama
A20: 81Z8 | B20: Weight Management Program - Basic / Asas / 基础 | C20: 1 | D20: 92.8 | E20: 758.62 | F20: 829.46 | G20: 639.8 | H20: 563.95 | I20: 510.84 | J20: 450.15 | K20: 758.62
A21: 81Z9 | B21: Weight Management Program - Advanced / Lanjutan / 高级 | C21: 1 | D21: 110.75 | E21: 911.53 | F21: 1003.87 | G21: 775.99 | H21: 684.84 | I21: 621.03 | J21: 548.1 | K21: 911.53
A22: 82Z0 | B22: Weight Management Program - Ultimate / Terunggul / 终极 | C22: 1 | D22: 133.7 | E22: 1097.19 | F22: 1206.87 | G22: 932.57 | H22: 822.86 | I22: 746.05 | J22: 658.27 | K22: 1097.19
A23: WEIGHT MANAGEMENT PROGRAM / Basic / Asas / 基础 •2 x Formula 1 • 1 x Herbal Aloe Concentrate - Mandarin Flavour • 1 x Tea Mix with Hibiscus - Original Flavour - 51g
A24: 3T32 | B24: Formula 1 - Cafe Latte Flavour / Perisa Cafe Latte / 拿铁味 | C24: 1 | D24: 92.8 | E24: 758.62 | F24: 829.46 | G24: 639.8 | H24: 563.95 | I24: 510.84 | J24: 450.15 | K24: 758.62
A25: 3T33 | B25: Formula 1 - Cookie Crunch Flavour / Perisa Cookie Crunch / 巧饼味 | C25: 1 | D25: 92.8 | E25: 758.62 | F25: 829.46 | G25: 639.8 | H25: 563.95 | I25: 510.84 | J25: 450.15 | K25: 758.62
A26: 3T34 | B26: Formula 1 - Smooth Chocolate Flavour / Perisa Smooth Coklat / 顺滑巧克力味 | C26: 1 | D26: 92.8 | E26: 758.62 | F26: 829.46 | G26: 639.8 | H26: 563.95 | I26: 510.84 | J26: 450.15 | K26: 758.62
A27: WEIGHT MANAGEMENT PROGRAM / Advanced / Lanjutan / 高级 •2 x Formula 1 • 1 x Formula 3 Blended Soy And Whey Protein Powder • 1 x Herbal Aloe Concentrate - Mandarin Flavour • 1 x Tea Mix with Hibiscus - Original Flavour - 51g
A28: 3T35 | B28: Formula 1 - Cafe Latte Flavour / Perisa Cafe Latte / 拿铁味 | C28: 1 | D28: 110.75 | E28: 911.53 | F28: 1003.87 | G28: 775.99 | H28: 684.84 | I28: 621.03 | J28: 548.1 | K28: 911.53
A29: 3T36 | B29: Formula 1 - Cookie Crunch Flavour / Perisa Cookie Crunch / 巧饼味 | C29: 1 | D29: 110.75 | E29: 911.53 | F29: 1003.87 | G29: 775.99 | H29: 684.84 | I29: 621.03 | J29: 548.1 | K29: 911.53
A30: 3T37 | B30: Formula 1 - Smooth Chocolate Flavour / Perisa Smooth Coklat / 顺滑巧克力味 | C30: 1 | D30: 110.75 | E30: 911.53 | F30: 1003.87 | G30: 775.99 | H30: 684.84 | I30: 621.03 | J30: 548.1 | K30: 911.53
A31: WEIGHT MANAGEMENT PROGRAM / Ultimate / Terunggul / 终极 •2 x Formula 1 • 1 x Formula 3 Blended Soy And Whey Protein Powder • 1 x Mixed Fibres With Inulin Powder- Apple Flavour • 1 x Herbal Aloe Concentrate - Mandarin Flavour • 1 x Tea Mix with Hibiscus - Original Flavour - 51g
A32: 3T38 | B32: Formula 1 - Cafe Latte Flavour / Perisa Cafe Latte / 拿铁味 | C32: 1 | D32: 133.7 | E32: 1097.19 | F32: 1206.87 | G32: 932.57 | H32: 822.86 | I32: 746.05 | J32: 658.27 | K32: 1097.19
A33: 3T39 | B33: Formula 1 - Cookie Crunch Flavour / Perisa Cookie Crunch / 巧饼味 | C33: 1 | D33: 133.7 | E33: 1097.19 | F33: 1206.87 | G33: 932.57 | H33: 822.86 | I33: 746.05 | J33: 658.27 | K33: 1097.19
A34: 3T40 | B34: Formula 1 - Smooth Chocolate Flavour / Perisa Smooth Coklat / 顺滑巧克力味 | C34: 1 | D34: 133.7 | E34: 1097.19 | F34: 1206.87 | G34: 932.57 | H34: 822.86 | I34: 746.05 | J34: 658.27 | K34: 1097.19
A35: Functional Pack / Pek Fungsian / 功能配套
A36: 1T49 | B36: Digestive+ 健康肠道配套 - Original Flavour 1 x Mixed Fibres With Inulin Powder Drink - Original Flavour 1 x Herbal Aloe Concentrate Mix - Mandarin Flavour 1 x Mesh Bag - Green 1 x Info Card | C36: 1 | D36: 47.9 | E36: 394.33 | F36: 431.15 | G36: 332.57 | H36: 293.13 | I36: 265.53 | J36: 233.98 | K36: 394.33
A37: 1T50 | B37: Digestive+ 健康肠道配套 - Apple Flavour 1 x Mixed Fibres With Inulin Powder Drink - Apple Flavour 1 x Herbal Aloe Concentrate Mix - Mandarin Flavour 1 x Mesh Bag - Green 1 x Info Card | C37: 1 | D37: 47.9 | E37: 394.33 | F37: 431.15 | G37: 332.57 | H37: 293.13 | I37: 265.53 | J37: 233.98 | K37: 394.33
A38: 1T52 | B38: DefenZ+ 免疫防护配套 3 x Immulift 1 x Multivitamins & Minerals 1 x Turmerix 336mg 1 x Mesh Bag - Purple 1 x Info Card | C38: 1 | D38: 70.75 | E38: 539.34 | F38: 589.71 | G38: 454.87 | H38: 400.94 | I38: 363.19 | J38: 320.04 | K38: 539.34
A39: 1T53 | B39: Flow+ 循环顺畅配套 1 x Omega 3 Fish Oil 1 x Niteworks 1 x Garlic Plus 1 x Mesh Bag - Red 1 x Info Card | C39: 1 | D39: 87.45 | E39: 675.34 | F39: 738.4 | G39: 569.56 | H39: 502.03 | I39: 454.76 | J39: 400.73 | K39: 675.34
A40: 1T55 | B40: Glow+ 焕亮美颜配套 1 x Collagen Plus Powder 1 x Celactivo 2 x Herbalife Moisturing Vitamin Mask 1 x Mesh Bag - Pink 1 x Info Card | C40: 1 | D40: 83.05 | E40: 634.53 | F40: 699.76 | G40: 541.13 | H40: 477.67 | I40: 433.26 | J40: 382.49 | K40: 634.53
...
